Traceback (most recent call last):
  File "/storage/chen/home/u250758/miniconda3/envs/cellrank/lib/python3.9/multiprocessing/process.py", line 315, in _bootstrap
    self.run()
  File "/storage/chen/home/u250758/miniconda3/envs/cellrank/lib/python3.9/multiprocessing/process.py", line 108, in run
    self._target(*self._args, **self._kwargs)
  File "/storage/chen/home/u250758/miniconda3/envs/cellrank/lib/python3.9/multiprocessing/managers.py", line 591, in _run_server
    server.serve_forever()
  File "/storage/chen/home/u250758/miniconda3/envs/cellrank/lib/python3.9/multiprocessing/managers.py", line 184, in serve_forever
    sys.exit(0)
SystemExit: 0

During handling of the above exception, another exception occurred:

Traceback (most recent call last):
  File "/storage/chen/home/u250758/miniconda3/envs/cellrank/lib/python3.9/multiprocessing/util.py", line 300, in _run_finalizers
    finalizer()
  File "/storage/chen/home/u250758/miniconda3/envs/cellrank/lib/python3.9/multiprocessing/util.py", line 224, in __call__
    res = self._callback(*self._args, **self._kwargs)
  File "/storage/chen/home/u250758/miniconda3/envs/cellrank/lib/python3.9/multiprocessing/util.py", line 133, in _remove_temp_dir
    rmtree(tempdir)
  File "/storage/chen/home/u250758/miniconda3/envs/cellrank/lib/python3.9/shutil.py", line 734, in rmtree
    _rmtree_safe_fd(fd, path, onerror)
  File "/storage/chen/home/u250758/miniconda3/envs/cellrank/lib/python3.9/shutil.py", line 690, in _rmtree_safe_fd
    onerror(os.unlink, fullname, sys.exc_info())
  File "/storage/chen/home/u250758/miniconda3/envs/cellrank/lib/python3.9/shutil.py", line 688, in _rmtree_safe_fd
    os.unlink(entry.name, dir_fd=topfd)
OSError: [Errno 16] Device or resource busy: '.nfs00000000969f1c2c000283f8'
